{
  "title": "Sync using callback - 2 callbacks, send an error at the second callback",
  "task": "sync",
  "taskData": {
    "type": "sync",
    "id": "taskId"
  },
  "steps": [
    {
      "func": "getBackendApprovals",
      "args": [
        {}
      ],
      "output": []
    },
    {
      "func": "fetch",
      "args": [
        {
          "signatureList": []
        }
      ],
      "callback": [
        [null, { "approvals": ["rawApproval.json"] }, true],
        ["System Unavailable", { "approvals": ["rawmoreApproval.json"] }, false]],
      "outputType": "Result.Success",
      "output": {}
    },
    {
      "func": "sendApprovals",
      "args": [
        {
          "approvals": [
            "transformedApproval.json"
          ],
          "rawApprovals": [
            "rawApproval.json"
          ],
          "transformedApprovals": [
            "transformedApproval.json"
          ]
        },
        {}
      ],
      "output": {}
    },
    {
      "func": "updateTask",
      "args": [
        "taskId",
        {
          "status": "InternalError",
          "meta": {
            "entity": "sdk",
            "message": "Unexpected error: \"System Unavailable\"",
            "taskType": "sync"
          }
        }
      ],
      "output": {}
    }
  ]
}